<mujoco model="j2n6s300">
    <compiler angle="radian" meshdir="meshes/" />
    <option timestep="0.01" gravity="0 0 -9.8" iterations="10" integrator="Euler"/>
    <size njmax="500" nconmax="100" />
    <asset>
        <mesh name="base" file="base.STL" />
        <mesh name="shoulder" file="shoulder.STL" />
        <mesh name="arm" file="arm.STL" />
        <mesh name="forearm" file="forearm.STL" />
        <mesh name="wrist" file="wrist.STL" />
        <mesh name="hand_3finger" file="hand_3finger.STL" />
        <mesh name="finger_proximal" file="finger_proximal.STL" />
        <mesh name="finger_distal" file="finger_distal.STL" />

	<texture name="groundplane" type="2d" builtin="checker" rgb1=".25 .26 .25" 
			rgb2=".22 .22 .22" width="100" height="100" mark="none" markrgb=".8 .8 .8"/>
    	<texture type="skybox" builtin="checker" rgb1="1 1 1" rgb2="1 1 1"
                 width="256" height="256"/>
        <texture name="texgeom" type="cube" builtin="flat" mark="cross" width="127" height="1278" rgb1="0.8 0.6 0.4" rgb2="0.8 0.6 0.4" markrgb="1 1 1" random="0.01" />
        <texture name="texplane" type="2d" builtin="checker" rgb1=".8 .8 .8" rgb2=".8 .8 .8" width="100" height="100" />
        <texture name="texplane_show" type="2d" builtin="checker" rgb1="0 0 0" rgb2="0.9 0.9 0.9" width="100" height="100" />

        <material name='MatPlane' texture="texplane" shininess="1" texrepeat="30 30" specular="1"  reflectance="0.5" />
        <material name='MatPlaneShow' texture="texplane_show" shininess="1" texrepeat="30 30" specular="1"  reflectance="0.5" />
        <material name='geom' texture="texgeom" texuniform="true" />
	<material name="MatViz" specular="1" shininess=".1" reflectance="0.5" rgba=".07 .07 .1 1"/>
	<material name="MatGnd" texture="groundplane"  texrepeat="5 5" specular="1" shininess=".3" reflectance="0.00001"/>

    </asset>

    <default>
	<geom margin="0.001"/>
        <joint limited="true" damping="0.5" armature=".01"/>
		
	<!--geom class for visual and collision geometry-->
	<default class ="vizNcoll"> 
		<geom material="MatViz" type="mesh" group="0"  contype="1" conaffinity="0"/>
		<joint pos="0 0 0" type="hinge"/>
	</default>	
	<default class ="ground"> 
		<geom material="MatPlane" type="plane" contype="1" conaffinity="1"/>
	</default>		
    </default>

    <worldbody>
	<light directional="true" cutoff="60" exponent="1" diffuse="1 1 1" specular=".1 .1 .1" pos="1 1 1.5" dir="-1 -1 -1.3"/>
        <geom name="ground" class="ground" pos="0 0 0" size="2 2 1"/>

        <geom type="mesh" rgba="0.792157 0.819608 0.933333 1" mesh="base" />
        <body name="j2n6s300_link_1" pos="0 0 0.15675" quat="0 0 1 0">
            <inertial pos="0 -0.002 -0.0605" mass="0.7477" diaginertia="0.00152032 0.00152032 0.00059816" />
            <joint name="j2n6s300_joint_1" pos="0 0 0" axis="0 0 1" limited="true" range="-6.28319 6.28319" />
            <geom type="mesh" rgba="0.792157 0.819608 0.933333 1" mesh="shoulder" />
            <body name="j2n6s300_link_2" pos="0 0.0016 -0.11875" quat="0 0 -0.707107 0.707107">
                <inertial pos="0 -0.2065 -0.01" quat="0.707107 0.707107 0 0" mass="0.99" diaginertia="0.0105022 0.0105022 0.000792" />
                <joint name="j2n6s300_joint_2" pos="0 0 0" axis="0 0 1" limited="true" range="0.820305 5.46288" />
                <geom type="mesh" rgba="0.792157 0.819608 0.933333 1" mesh="arm" />
                <body name="j2n6s300_link_3" pos="0 -0.41 0" quat="0 0 1 0">
                    <inertial pos="0 0.081 -0.0086" quat="0.707107 0.707107 0 0" mass="0.6763" diaginertia="0.00142022 0.00142022 0.000304335" />
                    <joint name="j2n6s300_joint_3" pos="0 0 0" axis="0 0 1" limited="true" range="0.331613 5.95157" />
                    <geom type="mesh" rgba="0.792157 0.819608 0.933333 1" mesh="forearm" />
                    <body name="j2n6s300_link_4" pos="0 0.2073 -0.0114" quat="0 0 -0.707107 0.707107">
                        <inertial pos="0 -0.037 -0.0642" quat="0.5 0.5 -0.5 0.5" mass="0.426367" diaginertia="0.0001428 7.73497e-05 7.73497e-05" />
                        <joint name="j2n6s300_joint_4" pos="0 0 0" axis="0 0 1" limited="true" range="-6.28319 6.28319" />
                        <geom type="mesh" rgba="0.792157 0.819608 0.933333 1" mesh="wrist" />
                        <body name="j2n6s300_link_5" pos="0 -0.03703 -0.06414" quat="0 0 0.5 0.866025">
                            <inertial pos="0 -0.037 -0.0642" quat="0.5 0.5 -0.5 0.5" mass="0.426367" diaginertia="0.0001428 7.73497e-05 7.73497e-05" />
                            <joint name="j2n6s300_joint_5" pos="0 0 0" axis="0 0 1" limited="true" range="-6.28319 6.28319" />
                            <geom type="mesh" rgba="0.792157 0.819608 0.933333 1" mesh="wrist" />
                            <body name="j2n6s300_link_6" pos="0 -0.03703 -0.06414" quat="0 0 0.5 0.866025">
                                <inertial pos="0 0 -0.06" quat="0.5 0.5 -0.5 0.5" mass="0.99" diaginertia="0.0005816 0.000345324 0.000345324" />
                                <joint name="j2n6s300_joint_6" pos="0 0 0" axis="0 0 1" limited="true" range="-6.28319 6.28319" />
                                <geom type="mesh" rgba="0.792157 0.819608 0.933333 1" mesh="hand_3finger" />
                                <body name="j2n6s300_link_finger_1" pos="0.00279 0.03126 -0.11467" quat="0.379408 -0.662973 -0.245899 0.596699">
                                    <inertial pos="0.044 -0.0015 0" quat="0.516726 0.516726 0.482695 0.482695" mass="0.02" diaginertia="1.1305e-05 9.885e-06 1.57999e-06" />
                                    <joint name="j2n6s300_joint_finger_1" pos="0 0 0" axis="0 0 1" limited="true" range="0 2" />
                                    <geom type="mesh" rgba="0.792157 0.819608 0.933333 1" mesh="finger_proximal" />
                                    <geom pos="0.044 -0.003 0" type="mesh" rgba="0.792157 0.819608 0.933333 1" mesh="finger_distal" />
                                </body>
                                <body name="j2n6s300_link_finger_2" pos="0.02226 -0.02707 -0.11482" quat="0.659653 -0.37146 0.601679 -0.254671">
                                    <inertial pos="0.044 -0.0015 0" quat="0.516726 0.516726 0.482695 0.482695" mass="0.02" diaginertia="1.1305e-05 9.885e-06 1.57999e-06" />
                                    <joint name="j2n6s300_joint_finger_2" pos="0 0 0" axis="0 0 1" limited="true" range="0 2" />
                                    <geom type="mesh" rgba="0.792157 0.819608 0.933333 1" mesh="finger_proximal" />
                                    <geom pos="0.044 -0.003 0" type="mesh" rgba="0.792157 0.819608 0.933333 1" mesh="finger_distal" />
                                </body>
                                <body name="j2n6s300_link_finger_3" pos="-0.02226 -0.02707 -0.11482" quat="0.601679 -0.254671 0.659653 -0.37146">
                                    <inertial pos="0.044 -0.0015 0" quat="0.516726 0.516726 0.482695 0.482695" mass="0.02" diaginertia="1.1305e-05 9.885e-06 1.57999e-06" />
                                    <joint name="j2n6s300_joint_finger_3" pos="0 0 0" axis="0 0 1" limited="true" range="0 2" />
                                    <geom type="mesh" rgba="0.792157 0.819608 0.933333 1" mesh="finger_proximal" />
                                    <geom pos="0.044 -0.003 0" type="mesh" rgba="0.792157 0.819608 0.933333 1" mesh="finger_distal" />
                                </body>
                            </body>
                        </body>
                    </body>
                </body>
            </body>
        </body>
	<body name="target1" pos="0.5 0.15 .035">
            <geom type="box" mass=".20" name="geom_object1" size="0.035 0.035 0.035" rgba="1 0 0 1" user="1" contype="1" conaffinity="1"/>
            <joint name="target1_joint" type="free" limited='false' damping="0" armature="0" user="010"/>
        </body>
    </worldbody>
    <!--actuator-->
    <actuator>
    <!--  ================= Torque actuators (Weren't present in the URDF. Added seperately)================= /-->
	<motor joint='j2n6s300_joint_1'     name='jaco_joint_1'  ctrllimited="true" gear="10" ctrlrange='-1.0 1.0'/>
	<motor joint='j2n6s300_joint_2'     name='jaco_joint_2' ctrllimited="true" gear="10" ctrlrange='-1.0 1.0'/>
	<motor joint='j2n6s300_joint_3'     name='jaco_joint_3' ctrllimited="true" gear="10" ctrlrange='-1.0 1.0'/>
	<motor joint='j2n6s300_joint_4'     name='jaco_joint_4' ctrllimited="true" gear="10" ctrlrange='-1.0 1.0'/>
	<motor joint='j2n6s300_joint_5'     name='jaco_joint_5' ctrllimited="true" gear="10" ctrlrange='-1.0 1.0'/>
	<motor joint='j2n6s300_joint_6'     name='jaco_joint_6' ctrllimited="true" gear="10" ctrlrange='-1.0 1.0'/>
	<!-- <motor tendon='finger'          name='Ajaco_fingers' gear="10" ctrlrange='-1 1'/> -->
	<motor joint='j2n6s300_joint_finger_1'     name='jaco_joint_finger_1' ctrllimited="true" gear='10' ctrlrange='-1.0 1.0'/>
	<motor joint='j2n6s300_joint_finger_2'  name='jaco_joint_finger_2' ctrllimited="true" gear='10' ctrlrange='-1.0 1.0'/>
	<motor joint='j2n6s300_joint_finger_3'  name='jaco_joint_finger_3' ctrllimited="true" gear='10' ctrlrange='-1.0 1.0'/>
    </actuator>

</mujoco>
